Workbook

Sheet Dashboard
A1: DINO DCF Dashboard
A2: Project summary
A3: Key results
A4: Metric | B4: 2026E | C4: 2030E | D4: CAGR / Δ | F4: Metric | G4: Value | H4: Scenario
A5: Revenue from sales (PLN thousand) | B5: ='Three-Statement Model'!H6 -> 39326450 | C5: ='Three-Statement Model'!L6 -> 65628074 | D5: =POWER(C5/B5,1/4)-1 -> 0.13658319 | F5: Implied share price | G5: ='DCF Valuation'!B26 -> 35.731345 | H5: Scenario 1
A6: EBITDA (PLN thousand) | B6: ='Three-Statement Model'!H15 -> 3100305.1 | C6: ='Three-Statement Model'!L15 -> 5736782.7 | D6: =POWER(C6/B6,1/4)-1 -> 0.16631535 | F6: Implied share price | G6: ='DCF Valuation'!B38 -> 44.8241 | H6: Scenario 2
A7: EBIT margin | B7: ='Three-Statement Model'!H19 -> 0.063835112 | C7: ='Three-Statement Model'!L19 -> 0.072413547 | D7: =C7-B7 -> 0.0085784345 | F7: Current share price | G7: ='DCF Valuation'!B27 -> 41
A8: WACC | B8: ='Debt and WACC'!H35 -> 0.092789233 | C8: ='Debt and WACC'!L35 -> 0.092789233 | D8: =C8-B8 -> 0 | F8: Premium / (discount) | G8: ='DCF Valuation'!B28 -> -0.12850378 | H8: Scenario 1
A9: Net debt / (net cash) | B9: ='Three-Statement Model'!H89 -> 581564.9 | C9: ='Three-Statement Model'!L89 -> -6648703.9 | D9: =C9-B9 -> -7230268.8 | F9: Premium / (discount) | G9: ='DCF Valuation'!B39 -> 0.09327074 | H9: Scenario 2
A10: Forecast assumptions
A11: Metric | B11: 2026E | C11: 2027E | D11: 2028E | E11: 2029E | F11: 2030E
A12: LFL revenue growth | B12: =Assumptions!B28 -> 0.055 | C12: =Assumptions!C28 -> 0.0535 | D12: =Assumptions!D28 -> 0.052 | E12: =Assumptions!E28 -> 0.0505 | F12: =Assumptions!F28 -> 0.049
A13: General inflation | B13: =Assumptions!B29 -> 0.035 | C13: =Assumptions!C29 -> 0.032 | D13: =Assumptions!D29 -> 0.029 | E13: =Assumptions!E29 -> 0.026 | F13: =Assumptions!F29 -> 0.023
A14: Gross margin | B14: =Assumptions!B30 -> 0.237 | C14: =Assumptions!C30 -> 0.238 | D14: =Assumptions!D30 -> 0.239 | E14: =Assumptions!E30 -> 0.24 | F14: =Assumptions!F30 -> 0.24
A15: Capital expenditures % of sales | B15: =Assumptions!B35 -> 0.061 | C15: =Assumptions!C35 -> 0.053 | D15: =Assumptions!D35 -> 0.045 | E15: =Assumptions!E35 -> 0.037 | F15: =Assumptions!F35 -> 0.029
A16: Target equity weight | B16: =Assumptions!B16 -> 0.95 | C16: =Assumptions!B16 -> 0.95 | D16: =Assumptions!B16 -> 0.95 | E16: =Assumptions!B16 -> 0.95 | F16: =Assumptions!B16 -> 0.95
A17: Target debt weight | B17: =Assumptions!B17 -> 0.05 | C17: =Assumptions!B17 -> 0.05 | D17: =Assumptions!B17 -> 0.05 | E17: =Assumptions!B17 -> 0.05 | F17: =Assumptions!B17 -> 0.05
A18: Historical / forecast summary
A19: Year | B19: Revenue from sales | C19: EBITDA | D19: EBIT margin | E19: UFCF | F19: WACC
A20: 2020 | B20: ='Three-Statement Model'!B6 -> 10125815 | C20: ='Three-Statement Model'!B15 -> 1036005 | D20: ='Three-Statement Model'!B19 -> 0.082744846 | F20: ='Debt and WACC'!B35 -> 0.037466574
A21: 2021 | B21: ='Three-Statement Model'!C6 -> 13362012 | C21: ='Three-Statement Model'!C15 -> 1271336 | D21: ='Three-Statement Model'!C19 -> 0.076634642 | F21: ='Debt and WACC'!C35 -> 0.04208357
A22: 2022 | B22: ='Three-Statement Model'!D6 -> 19801622 | C22: ='Three-Statement Model'!D15 -> 1837948 | D22: ='Three-Statement Model'!D19 -> 0.077661264 | F22: ='Debt and WACC'!D35 -> 0.086099834
A23: 2023 | B23: ='Three-Statement Model'!E6 -> 25666255 | C23: ='Three-Statement Model'!E15 -> 2232683 | D23: ='Three-Statement Model'!E19 -> 0.073086432 | F23: ='Debt and WACC'!E35 -> 0.089760004
A24: 2024 | B24: ='Three-Statement Model'!F6 -> 29273792 | C24: ='Three-Statement Model'!F15 -> 2317509 | D24: ='Three-Statement Model'!F19 -> 0.065189026 | F24: ='Debt and WACC'!F35 -> 0.088054899
A25: 2025 | B25: ='Three-Statement Model'!G6 -> 33634155 | C25: ='Three-Statement Model'!G15 -> 2546313 | D25: ='Three-Statement Model'!G19 -> 0.060690747 | F25: ='Debt and WACC'!G35 -> 0.088388239
A26: 2026 | B26: ='Three-Statement Model'!H6 -> 39326450 | C26: ='Three-Statement Model'!H15 -> 3100305.1 | D26: ='Three-Statement Model'!H19 -> 0.063835112 | E26: ='DCF Valuation'!B14 -> -691342.74 | F26: ='Debt and WACC'!H35 -> 0.092789233
A27: 2027 | B27: ='Three-Statement Model'!I6 -> 45510536 | C27: ='Three-Statement Model'!I15 -> 3698090.1 | D27: ='Three-Statement Model'!I19 -> 0.06625789 | E27: ='DCF Valuation'!C14 -> 850042.42 | F27: ='Debt and WACC'!I35 -> 0.092789233
A28: 2028 | B28: ='Three-Statement Model'!J6 -> 51967772 | C28: ='Three-Statement Model'!J15 -> 4347000 | D28: ='Three-Statement Model'!J19 -> 0.068647998 | E28: ='DCF Valuation'!D14 -> 1474709.3 | F28: ='Debt and WACC'!J35 -> 0.092789233
A29: 2029 | B29: ='Three-Statement Model'!K6 -> 58713668 | C29: ='Three-Statement Model'!K15 -> 5051305.9 | D29: ='Three-Statement Model'!K19 -> 0.071032878 | E29: ='DCF Valuation'!E14 -> 2237511.7 | F29: ='Debt and WACC'!K35 -> 0.092789233
A30: 2030 | B30: ='Three-Statement Model'!L6 -> 65628074 | C30: ='Three-Statement Model'!L15 -> 5736782.7 | D30: ='Three-Statement Model'!L19 -> 0.072413547 | E30: ='DCF Valuation'!F14 -> 3098698.5 | F30: ='Debt and WACC'!L35 -> 0.092789233

Sheet Assumptions
A1: Assumptions
A2: Static valuation / model assumptions
A3: Metric | B3: Value | H3: Source/notes
A4: EV/EBITDA multiple | B4: 15
A5: Risk-free rate | B5: 0.0588 | H5: Polish 10-year benchmark in 2026; forward-looking WACC assumption, rate as of 23 May 2026
A6: Beta | B6: =(1/3*1)+(2/3*0.51) -> 0.67333333 | H6: Blume-adjusted equity beta assumption
A7: Equity risk premium | B7: 0.0533 | H7: Market risk premium assumption
A8: Terminal growth rate | B8: 0.025
A9: Current share price (PLN) | B9: ='Source Data'!G104 -> 41 | H9: Price as of 2 Jan 2026
A10: Number of shares (thousand) | B10: ='Source Data'!G101 -> 980400 | H10: Linked to the number of shares in 2025; 2020-2024 were 1/10 of 2025
A11: Days in year | B11: 365 | H11: Used for working capital days
A12: Unit divisor | B12: 1000 | H12: Used for unit conversion
A13: Minimum cash level % of sales | B13: 0.02
A14: Interest income rate on average cash | B14: 0.02
A15: Statutory tax rate | B15: 0.19
A16: Target equity weight | B16: 0.95
A17: Target debt weight | B17: =1-B16 -> 0.05
A18: <1 Year store productivity (% of mature store productivity) | B18: 0.6
A19: 1-2 Years store productivity (% of mature store productivity) | B19: 0.8
A20: Historical market assumptions
A21: Metric | B21: 2020A | C21: 2021A | D21: 2022A | E21: 2023A | F21: 2024A | G21: 2025A | H21: Source / notes
A22: DINO market price / share (PLN) | B22: ='Source Data'!B104 -> 200 | C22: ='Source Data'!C104 -> 300 | D22: ='Source Data'!D104 -> 330 | E22: ='Source Data'!E104 -> 420 | F22: ='Source Data'!F104 -> 400 | G22: ='Source Data'!G104 -> 41
A23: Risk-free rate | B23: ='Source Data'!B105 -> 0.015 | C23: ='Source Data'!C105 -> 0.0194 | D23: ='Source Data'!D105 -> 0.0605 | E23: ='Source Data'!E105 -> 0.0581 | F23: ='Source Data'!F105 -> 0.0553 | G23: ='Source Data'!G105 -> 0.055
A24: Number of shares (thousand) | B24: ='Source Data'!B101 -> 98040 | C24: ='Source Data'!C101 -> 98040 | D24: ='Source Data'!D101 -> 98040 | E24: ='Source Data'!E101 -> 98040 | F24: ='Source Data'!F101 -> 98040 | G24: ='Source Data'!G101 -> 980400
A25: Market capitalisation (PLN thousand) | B25: =B22*B24 -> 19608000 | C25: =C22*C24 -> 29412000 | D25: =D22*D24 -> 32353200 | E25: =E22*E24 -> 41176800 | F25: =F22*F24 -> 39216000 | G25: =G22*G24 -> 40196400
A26: Operating forecast assumptions
A27: Metric | B27: 2026E | C27: 2027E | D27: 2028E | E27: 2029E | F27: 2030E | H27: Source / notes
A28: LFL revenue growth | B28: 0.055 | C28: 0.0535 | D28: 0.052 | E28: 0.0505 | F28: 0.049
A29: General inflation | B29: 0.035 | C29: 0.032 | D29: 0.029 | E29: 0.026 | F29: 0.023
A30: Gross margin | B30: 0.237 | C30: 0.238 | D30: 0.239 | E30: 0.24 | F30: 0.24
A31: Growth in number of stores | B31: 0.1 | C31: 0.09 | D31: 0.08 | E31: 0.07 | F31: 0.06
A32: Other operating income % of sales | B32: 0.0008 | C32: 0.0008 | D32: 0.0008 | E32: 0.0008 | F32: 0.0008
A33: Depreciation and amortisation % of sales | B33: 0.015 | C33: 0.015 | D33: 0.015 | E33: 0.015 | F33: 0.015
A34: Selling and marketing expenses | B34: 0.1647 | C34: 0.1636 | D34: 0.1625 | E34: 0.1614 | F34: 0.1603
A35: Capital expenditures % of sales | B35: 0.061 | C35: 0.053 | D35: 0.045 | E35: 0.037 | F35: 0.029
A36: Inventory days | B36: 50 | C36: 50 | D36: 49.5 | E36: 49 | F36: 48.5
A37: Receivables days | B37: 4 | C37: 4 | D37: 4 | E37: 4 | F37: 4
A38: Payables days | B38: 74 | C38: 74 | D38: 73.5 | E38: 73 | F38: 72.5
A39: Non-current asset allocation assumptions
A40: Metric | B40: 2026E | C40: 2027E | D40: 2028E | E40: 2029E | F40: 2030E | H40: Source / notes
...

Sheet Source Data
A1: Source Data
A3: Historical statement of profit or loss
A4: Line item | B4: 2020 | C4: 2021 | D4: 2022 | E4: 2023 | F4: 2024 | G4: 2025
A5: Revenue from sales | B5: 10125815 | C5: 13362012 | D5: 19801622 | E5: 25666255 | F5: 29273792 | G5: 33634155
A6: Cost of sales | B6: -7521986 | C6: -10038342 | D6: -15038630 | E6: -19741459 | F6: -22463233 | G6: -25723078
A7: Gross profit on sales | B7: 2603829 | C7: 3323670 | D7: 4762992 | E7: 5924796 | F7: 6810559 | G7: 7911077
A8: Other operating income | B8: 7598 | C8: 14364 | D8: 16282 | E8: 13477 | F8: 24185 | G8: 29231
A9: Selling and marketing expenses | B9: -1668084 | C9: -2181963 | D9: -3080061 | E9: -3878421 | F9: -4678717 | G9: -5576262
A10: General and administrative expenses | B10: -99783 | C10: -117285 | D10: -143217 | E10: -173736 | F10: -233653 | G10: -302944
A11: Other operating expenses | B11: -5701 | C11: -14793 | D11: -18177 | E11: -10261 | F11: -14044 | G11: -19820
A12: Operating profit | B12: 837859 | C12: 1023993 | D12: 1537819 | E12: 1875855 | F12: 1908330 | G12: 2041282
A13: Finance income | B13: 3237 | C13: 1119 | D13: 5092 | E13: 10442 | F13: 6657 | G13: 8316
A14: Interest expense - debt / leases / bonds | B14: -30379 | C14: -26155 | D14: -124832 | E14: -127285 | F14: -90957 | G14: -67946
A15: Interest expense - trade payables | B15: -18139 | C15: -20434 | D15: -15839 | E15: -19600 | F15: -29836 | G15: -54614
... A23: Profit attributable to non-controlling interests | B23: 0 | C23: 0 | D23: 0 | E23: 0 | F23: 749 | G23: 437
A24: Historical statement of financial position
A25: Line item | B25: 2020 | C25: 2021 | D25: 2022 | E25: 2023 | F25: 2024 | G25: 2025
A26: Property, plant and equipment | B26: 3749480 | C26: 4911353 | D26: 6070032 | E26: 6874672 | F26: 8230915 | G26: 9774681
A27: Right-of-use assets | B27: 184538 | C27: 139931 | D27: 105116 | E27: 93499 | F27: 141350 | G27: 217006
A28: Intangible assets | B28: 99050 | C28: 96947 | D28: 94737 | E28: 115056 | F28: 169964 | G28: 176185
A29: Other non-financial assets (non-current) | B29: 6 | C29: 0 | D29: 0 | E29: 0 | F29: 0 | G29: 0
A30: Deferred tax assets | B30: 20738 | C30: 35116 | D30: 26468 | E30: 41323 | F30: 74149 | G30: 31376
A31: Total non-current assets | B31: 4053812 | C31: 5183347 | D31: 6296353 | E31: 7124550 | F31: 8616378 | G31: 10199248
A32: Inventories | B32: 875147 | C32: 1373463 | D32: 1978778 | E32: 2638859 | F32: 3081444 | G32: 3548100
A33: Trade and other receivables | B33: 86822 | C33: 144012 | D33: 274872 | E33: 330389 | F33: 376480 | G33: 372038
A34: Income tax receivables | B34: 2 | C34: 55 | D34: 0 | E34: 103 | F34: 220 | G34: 18596
A35: Other non-financial assets (current) | B35: 73367 | C35: 47712 | D35: 69096 | E35: 64049 | F35: 88186 | G35: 76477
A36: Other financial assets | B36: 942 | C36: 1327 | D36: 1242 | E36: 1376 | F36: 2064 | G36: 2007
... A65: TOTAL EQUITY AND LIABILITIES | B65: 5570510 | C65: 7168531 | D65: 9003059 | E65: 10377715 | F65: 13055794 | G65: 15171280
A66: Historical statement of cash flows
A67: Line item | B67: 2020 | C67: 2021 | D67: 2022 | E67: 2023 | F67: 2024 | G67: 2025
A68: Depreciation and amortisation | B68: 198146 | C68: 247343 | D68: 300129 | E68: 356828 | F68: 409179 | G68: 505031
A69: Profit before tax | B69: =B19 -> 789000 | C69: =C19 -> 978409 | D69: =D19 -> 1401618 | E69: =E19 -> 1738981 | F69: =F19 -> 1793563 | G69: =G19 -> 1926653
A70: Income tax paid | B70: -138680 | C70: -173004 | D70: -234653 | E70: -291839 | F70: -417176 | G70: -362312
A71: Interest expense | B71: 52012 | C71: 46645 | D71: 141293 | E71: 147316 | F71: 121353 | G71: 122837
A72: Change in receivables | B72: -43201 | C72: -24880 | D72: -152796 | E72: -54245 | F72: -55966 | G72: 14973
A73: Change in inventories | B73: -251152 | C73: -498316 | D73: -605315 | E73: -660081 | F73: -424123 | G73: -466656
A74: Change in liabilities excluding borrowings and loans | B74: 197916 | C74: 728449 | D74: 366502 | E74: 537055 | F74: 1126352 | G74: 948166
A75: Other | B75: =B76-SUM(B68:B74) -> 15881 | C75: =C76-SUM(C68:C74) -> 21685 | D75: =D76-SUM(D68:D74) -> 36644 | E75: =E76-SUM(E68:E74) -> -2475 | F75: =F76-SUM(F68:F74) -> 4271 | G75: =G76-SUM(G68:G74) -> 8753
A76: Net cash from operating activities | B76: 819922 | C76: 1326331 | D76: 1253422 | E76: 1771540 | F76: 2557453 | G76: 2697445
...

Sheet Operating Drivers
A1: Operating drivers / revenue build
A2: Formula-driven operating bridge. Forecast revenue is driven by LFL growth; store metrics are operating KPIs.
A3: Metric | B3: 2020 | C3: 2021 | D3: 2022 | E3: 2023 | F3: 2024 | G3: 2025 | H3: 2026 | I3: 2027 | J3: 2028 | K3: 2029 | L3: 2030
A4: Period | B4: 2020A | C4: 2021A | D4: 2022A | E4: 2023A | F4: 2024A | G4: 2025A | H4: 2026E | I4: 2027E | J4: 2028E | K4: 2029E | L4: 2030E
A5: Store count bridge and revenue build
A6: Number of stores (#) | B6: ='Source Data'!B96 -> 1473 | C6: ='Source Data'!C96 -> 1815 | D6: ='Source Data'!D96 -> 2156 | E6: ='Source Data'!E96 -> 2406 | F6: ='Source Data'!F96 -> 2688 | G6: ='Source Data'!G96 -> 3033 | H6: =G6*(1+Assumptions!B31) -> 3336.3 | I6: =H6*(1+Assumptions!C31) -> 3636.567 | J6: =I6*(1+Assumptions!D31) -> 3927.4924 | K6: =J6*(1+Assumptions!E31) -> 4202.4168 | L6: =K6*(1+Assumptions!F31) -> 4454.5618
A7: Growth in number of stores | B7: 0 | C7: =C6/B6-1 -> 0.23217923 | D7: =D6/C6-1 -> 0.18787879 | E7: =E6/D6-1 -> 0.11595547 | F7: =F6/E6-1 -> 0.11720698 | G7: =G6/F6-1 -> 0.12834821 | H7: =Assumptions!B31 -> 0.1 | I7: =Assumptions!C31 -> 0.09 | J7: =Assumptions!D31 -> 0.08 | K7: =Assumptions!E31 -> 0.07 | L7: =Assumptions!F31 -> 0.06
A8: Sales area (thousand m²) | B8: ='Source Data'!B97 -> 573 | C8: ='Source Data'!C97 -> 710 | D8: ='Source Data'!D97 -> 848 | E8: ='Source Data'!E97 -> 948 | F8: ='Source Data'!F97 -> 1061 | G8: ='Source Data'!G97 -> 1200 | H8: =H6*H13/Assumptions!$B$12 -> 1323.3363 | I8: =I6*I13/Assumptions!$B$12 -> 1446.0731 | J8: =J6*J13/Assumptions!$B$12 -> 1565.6865 | K8: =K6*K13/Assumptions!$B$12 -> 1679.4869 | L8: =L6*L13/Assumptions!$B$12 -> 1784.7107
A9: Sales area growth | C9: =C8/B8-1 -> 0.2390925 | D9: =D8/C8-1 -> 0.1943662 | E9: =E8/D8-1 -> 0.11792453 | F9: =F8/E8-1 -> 0.11919831 | G9: =G8/F8-1 -> 0.13100848 | H9: =H8/G8-1 -> 0.10278025 | I9: =I8/H8-1 -> 0.092748029 | J9: =J8/I8-1 -> 0.082715971 | ... L9: =L8/K8-1 -> 0.062652335
A10: <1 Year stores (#) | B10: 0 | C10: =C6-B6 -> 342 | D10: =D6-C6 -> 341 | E10: =E6-D6 -> 250 | F10: =F6-E6 -> 282 | G10: =G6-F6 -> 345 | H10: =H6-G6 -> 303.3 | I10: =I6-H6 -> 300.267 | J10: =J6-I6 -> 290.92536 | ... L10: =L6-K6 -> 252.14501
A11: 1-2 Year stores (#) | B11: 0 | C11: 0 | D11: =C10 -> 342 | E11: =D10 -> 341 | F11: =E10 -> 250 | G11: =F10 -> 282 | H11: =G10 -> 345 | I11: =H10 -> 303.3 | J11: =I10 -> 300.267 | K11: =J10 -> 290.92536 | L11: =K10 -> 274.92447
A12: Mature Stores | B12: =B6 -> 1473 | C12: =B6 -> 1473 | D12: =B6 -> 1473 | E12: =C6 -> 1815 | F12: =D6 -> 2156 | G12: =E6 -> 2406 | H12: =F6 -> 2688 | I12: =G6 -> 3033 | J12: =H6 -> 3336.3 | K12: =I6 -> 3636.567 | L12: =J6 -> 3927.4924
A13: Average sales area / store (m²) | B13: ='Source Data'!B98 -> 389.00204 | C13: ='Source Data'!C98 -> 391.18457 | D13: ='Source Data'!D98 -> 393.32096 | E13: ='Source Data'!E98 -> 394.01496 | F13: ='Source Data'!F98 -> 394.71726 | G13: ='Source Data'!G98 -> 395.64787 | H13: =G13+1 -> 396.64787 | I13: =H13+1 -> 397.64787 | J13: =I13+1 -> 398.64787 | K13: =J13+1 -> 399.64787 | L13: =K13+1 -> 400.64787
A14: Revenue / store (PLN thousand) | B14: =B17/B6 -> 6874.2804 | C14: =C17/C6 -> 7361.9901 | D14: =D17/D6 -> 9184.4258 | E14: =E17/E6 -> 10667.604 | F14: =F17/F6 -> 10890.548 | G14: =G17/G6 -> 11089.402 | H14: =H17/H6 -> 11787.444 | I14: =I17/I6 -> 12514.697 | ... L14: =L17/L6 -> 14732.779
A15: Revenue / store growth | B15: 0 | C15: =C14/B14-1 -> 0.070947019 | D15: =D14/C14-1 -> 0.24754661 | E15: =E14/D14-1 -> 0.16148839 | F15: =F14/E14-1 -> 0.020899137 | G15: =G14/F14-1 -> 0.018259317 | H15: =H14/G14-1 -> 0.062946811 | I15: =I14/H14-1 -> 0.061697293 | J15: =J14/I14-1 -> 0.057300386 | ... L15: =L14/K14-1 -> 0.054495128
A16: Revenue per mature store | B16: =B17/(B12+Assumptions!$B$19*B11+Assumptions!$B$18*B10) -> 6874.2804 | C16: =C17/(C12+Assumptions!$B$19*C11+Assumptions!$B$18*C10) -> 7962.1094 | D16: =D17/(D12+Assumptions!$B$19*D11+Assumptions!$B$18*D10) -> 10148.433 | E16: =E17/(E12+Assumptions!$B$19*E11+Assumptions!$B$18*E10) -> 11469.414 | F16: =F17/(F12+Assumptions!$B$19*F11+Assumptions!$B$18*F10) -> 11592.663 | G16: =G17/(G12+Assumptions!$B$19*G11+Assumptions!$B$18*G10) -> 11848.853 | H16: =G16*(1+Assumptions!B28) -> 12500.54 | I16: =H16*(1+Assumptions!C28) -> 13169.319 | J16: =I16*(1+Assumptions!D28) -> 13854.124 | K16: =J16*(1+Assumptions!E28) -> 14553.757 | L16: =K16*(1+Assumptions!F28) -> 15266.891
A17: Revenue from sales (PLN thousand) | B17: ='Source Data'!B5 -> 10125815 | C17: ='Source Data'!C5 -> 13362012 | D17: ='Source Data'!D5 -> 19801622 | E17: ='Source Data'!E5 -> 25666255 | F17: ='Source Data'!F5 -> 29273792 | G17: ='Source Data'!G5 -> 33634155 | H17: =(H16*(H12+Assumptions!$B$19*H11+Assumptions!$B$18*H10)) -> 39326450 | I17: =(I16*(I12+Assumptions!$B$19*I11+Assumptions!$B$18*I10)) -> 45510536 | J17: =(J16*(J12+Assumptions!$B$19*J11+Assumptions!$B$18*J10)) -> 51967772 | K17: =(K16*(K12+Assumptions!$B$19*K11+Assumptions!$B$18*K10)) -> 58713668 | L17: =(L16*(L12+Assumptions!$B$19*L11+Assumptions!$B$18*L10)) -> 65628074
A18: Revenue growth | B18: 0 | C18: =C17/B17-1 -> 0.31959867 | D18: =D17/C17-1 -> 0.48193416 | E18: =E17/D17-1 -> 0.29616932 | F18: =F17/E17-1 -> 0.14055564 | G18: =G17/F17-1 -> 0.14895108 | H18: =H17/G17-1 -> 0.16924149 | I18: =I17/H17-1 -> 0.15725005 | J18: =J17/I17-1 -> 0.14188442 | ... L18: =L17/K17-1 -> 0.11776484
A19: Gross margin | B19: ='Source Data'!B7/B17 -> 0.2571476 | C19: ='Source Data'!C7/C17 -> 0.24874023 | D19: ='Source Data'!D7/D17 -> 0.24053545 | E19: ='Source Data'!E7/E17 -> 0.23083991 | F19: ='Source Data'!F7/F17 -> 0.23265039 | G19: ='Source Data'!G7/G17 -> 0.23520963 | H19: =Assumptions!B30 -> 0.237 | I19: =Assumptions!C30 -> 0.238 | J19: =Assumptions!D30 -> 0.239 | K19: =Assumptions!E30 -> 0.24 | L19: =Assumptions!F30 -> 0.24
A20: EBITDA margin | B20: ='Three-Statement Model'!B15/'Three-Statement Model'!B6 -> 0.10231325 | C20: ='Three-Statement Model'!C15/'Three-Statement Model'!C6 -> 0.095145551 | D20: ='Three-Statement Model'!D15/'Three-Statement Model'!D6 -> 0.092818053 | E20: ='Three-Statement Model'!E15/'Three-Statement Model'!E6 -> 0.086989045 | F20: ='Three-Statement Model'!F15/'Three-Statement Model'!F6 -> 0.079166683 | G20: ='Three-Statement Model'!G15/'Three-Statement Model'!G6 -> 0.075706168 | H20: ='Three-Statement Model'!H15/'Three-Statement Model'!H6 -> 0.078835112 | I20: ='Three-Statement Model'!I15/'Three-Statement Model'!I6 -> 0.08125789 | ... L20: ='Three-Statement Model'!L15/'Three-Statement Model'!L6 -> 0.087413547
A21: EBIT margin | B21: ='Three-Statement Model'!B18/'Three-Statement Model'!B6 -> 0.082744846 | C21: ='Three-Statement Model'!C18/'Three-Statement Model'!C6 -> 0.076634642 | D21: ='Three-Statement Model'!D18/'Three-Statement Model'!D6 -> 0.077661264 | E21: ='Three-Statement Model'!E18/'Three-Statement Model'!E6 -> 0.073086432 | F21: ='Three-Statement Model'!F18/'Three-Statement Model'!F6 -> 0.065189026 | G21: ='Three-Statement Model'!G18/'Three-Statement Model'!G6 -> 0.060690747 | H21: ='Three-Statement Model'!H18/'Three-Statement Model'!H6 -> 0.063835112 | I21: ='Three-Statement Model'!I18/'Three-Statement Model'!I6 -> 0.06625789 | ... L21: ='Three-Statement Model'!L18/'Three-Statement Model'!L6 -> 0.072413547
A22: Capital expenditures % of sales | B22: =-'Three-Statement Model'!B35/'Three-Statement Model'!B6 -> 0.098957467 | C22: =-'Three-Statement Model'!C35/'Three-Statement Model'!C6 -> 0.099955306 | D22: =-'Three-Statement Model'!D35/'Three-Statement Model'!D6 -> 0.073019523 | E22: =-'Three-Statement Model'!E35/'Three-Statement Model'!E6 -> 0.045696694 | F22: =-'Three-Statement Model'!F35/'Three-Statement Model'!F6 -> 0.05335537 | G22: =-'Three-Statement Model'!G35/'Three-Statement Model'!G6 -> 0.062051299 | H22: =-'Three-Statement Model'!H35/'Three-Statement Model'!H6 -> 0.061 | I22: =-'Three-Statement Model'!I35/'Three-Statement Model'!I6 -> 0.053 | ... L22: =-'Three-Statement Model'!L35/'Three-Statement Model'!L6 -> 0.029
A23: Operating net working capital % of sales | B23: ='Three-Statement Model'!B90/'Three-Statement Model'!B6 -> -0.077554844 | C23: ='Three-Statement Model'!C90/'Three-Statement Model'!C6 -> -0.078189048 | D23: ='Three-Statement Model'!D90/'Three-Statement Model'!D6 -> -0.034259012 | E23: ='Three-Statement Model'!E90/'Three-Statement Model'!E6 -> -0.021349277 | F23: ='Three-Statement Model'!F90/'Three-Statement Model'!F6 -> -0.042793909 | G23: ='Three-Statement Model'!G90/'Three-Statement Model'!G6 -> -0.050406023 | H23: ='Three-Statement Model'!H90/'Three-Statement Model'!H6 -> -0.019823991 | I23: ='Three-Statement Model'!I90/'Three-Statement Model'!I6 -> -0.020139293 | ... L23: ='Three-Statement Model'!L90/'Three-Statement Model'!L6 -> -0.021023551

Sheet Three-Statement Model
A1: Integrated three-statement model
A2: All non-input cells are formula-driven from the Source Data and Assumptions sheets. Hardcoded values are isolated exclusively in the Source Data and Assumptions sheets.
A3: Metric | B3: 2020 | C3: 2021 | D3: 2022 | E3: 2023 | F3: 2024 | G3: 2025 | H3: 2026 | I3: 2027 | J3: 2028 | K3: 2029 | L3: 2030
A4: Period | B4: 2020A | C4: 2021A | D4: 2022A | E4: 2023A | F4: 2024A | G4: 2025A | H4: 2026E | I4: 2027E | J4: 2028E | K4: 2029E | L4: 2030E
A5: Statement of profit or loss
A6: Revenue from sales | B6: ='Source Data'!B5 -> 10125815 | C6: ='Source Data'!C5 -> 13362012 | D6: ='Source Data'!D5 -> 19801622 | E6: ='Source Data'!E5 -> 25666255 | F6: ='Source Data'!F5 -> 29273792 | G6: ='Source Data'!G5 -> 33634155 | H6: ='Operating Drivers'!H17 -> 39326450 | I6: ='Operating Drivers'!I17 -> 45510536 | J6: ='Operating Drivers'!J17 -> 51967772 | K6: ='Operating Drivers'!K17 -> 58713668 | L6: ='Operating Drivers'!L17 -> 65628074
A7: Revenue growth | C7: =C6/B6-1 -> 0.31959867 | D7: =D6/C6-1 -> 0.48193416 | E7: =E6/D6-1 -> 0.29616932 | F7: =F6/E6-1 -> 0.14055564 | G7: =G6/F6-1 -> 0.14895108 | H7: =H6/G6-1 -> 0.16924149 | I7: =I6/H6-1 -> 0.15725005 | J7: =J6/I6-1 -> 0.14188442 | ... L7: =L6/K6-1 -> 0.11776484
A8: Cost of sales | B8: ='Source Data'!B6 -> -7521986 | C8: ='Source Data'!C6 -> -10038342 | D8: ='Source Data'!D6 -> -15038630 | E8: ='Source Data'!E6 -> -19741459 | F8: ='Source Data'!F6 -> -22463233 | G8: ='Source Data'!G6 -> -25723078 | H8: =-H6*(1-Assumptions!B30) -> -30006081 | I8: =-I6*(1-Assumptions!C30) -> -34679028 | J8: =-J6*(1-Assumptions!D30) -> -39547474 | K8: =-K6*(1-Assumptions!E30) -> -44622388 | L8: =-L6*(1-Assumptions!F30) -> -49877336
A9: Gross profit | B9: =B6+B8 -> 2603829 | C9: =C6+C8 -> 3323670 | D9: =D6+D8 -> 4762992 | E9: =E6+E8 -> 5924796 | F9: =F6+F8 -> 6810559 | G9: =G6+G8 -> 7911077 | H9: =H6+H8 -> 9320368.6 | I9: =I6+I8 -> 10831508 | ... L9: =L6+L8 -> 15750738
A10: Gross margin | B10: =B9/B6 -> 0.2571476 | C10: =C9/C6 -> 0.24874023 | D10: =D9/D6 -> 0.24053545 | E10: =E9/E6 -> 0.23083991 | F10: =F9/F6 -> 0.23265039 | G10: =G9/G6 -> 0.23520963 | H10: =H9/H6 -> 0.237 | I10: =I9/I6 -> 0.238 | ... L10: =L9/L6 -> 0.24
A11: Other operating income | B11: ='Source Data'!B8 -> 7598 | C11: ='Source Data'!C8 -> 14364 | D11: ='Source Data'!D8 -> 16282 | E11: ='Source Data'!E8 -> 13477 | F11: ='Source Data'!F8 -> 24185 | G11: ='Source Data'!G8 -> 29231 | H11: =H6*Assumptions!B32 -> 31461.16 | I11: =I6*Assumptions!C32 -> 36408.429 | J11: =J6*Assumptions!D32 -> 41574.217 | K11: =K6*Assumptions!E32 -> 46970.935 | L11: =L6*Assumptions!F32 -> 52502.459
A12: Selling and marketing expenses | B12: ='Source Data'!B9 -> -1668084 | C12: ='Source Data'!C9 -> -2181963 | D12: ='Source Data'!D9 -> -3080061 | E12: ='Source Data'!E9 -> -3878421 | F12: ='Source Data'!F9 -> -4678717 | G12: ='Source Data'!G9 -> -5576262 | H12: =-H6*Assumptions!B34 -> -6477066.2 | I12: =-I6*Assumptions!C34 -> -7445523.6 | J12: =-J6*Assumptions!D34 -> -8444762.9 | K12: =-K6*Assumptions!E34 -> -9476386.1 | L12: =-L6*Assumptions!F34 -> -10520180
A13: General and administrative expenses | B13: ='Source Data'!B10 -> -99783 | C13: ='Source Data'!C10 -> -117285 | D13: ='Source Data'!D10 -> -143217 | E13: ='Source Data'!E10 -> -173736 | F13: ='Source Data'!F10 -> -233653 | G13: ='Source Data'!G10 -> -302944 | H13: =G13*(1+'Operating Drivers'!H7+Assumptions!B29) -> -343841.44 | I13: =H13*(1+'Operating Drivers'!I7+Assumptions!C29) -> -385790.1 | J13: =I13*(1+'Operating Drivers'!J7+Assumptions!D29) -> -427841.22 | K13: =J13*(1+'Operating Drivers'!K7+Assumptions!E29) -> -468913.97 | L13: =K13*(1+'Operating Drivers'!L7+Assumptions!F29) -> -507833.83
A14: Other operating expenses | B14: ='Source Data'!B11 -> -5701 | C14: ='Source Data'!C11 -> -14793 | D14: ='Source Data'!D11 -> -18177 | E14: ='Source Data'!E11 -> -10261 | F14: ='Source Data'!F11 -> -14044 | G14: ='Source Data'!G11 -> -19820 | H14: =G14*(1+Assumptions!B29) -> -20513.7 | I14: =H14*(1+Assumptions!C29) -> -21170.138 | J14: =I14*(1+Assumptions!D29) -> -21784.072 | K14: =J14*(1+Assumptions!E29) -> -22350.458 | L14: =K14*(1+Assumptions!F29) -> -22864.519
A15: EBITDA | B15: =SUM(B6,B8,B11,B12,B13,B14,-B17) -> 1036005 | C15: =SUM(C6,C8,C11,C12,C13,C14,-C17) -> 1271336 | D15: =SUM(D6,D8,D11,D12,D13,D14,-D17) -> 1837948 | E15: =SUM(E6,E8,E11,E12,E13,E14,-E17) -> 2232683 | F15: =SUM(F6,F8,F11,F12,F13,F14,-F17) -> 2317509 | G15: =SUM(G6,G8,G11,G12,G13,G14,-G17) -> 2546313 | H15: =SUM(H6,H8,H11,H12,H13,H14,-H17) -> 3100305.1 | I15: =SUM(I6,I8,I11,I12,I13,I14,-I17) -> 3698090.1 | ... L15: =SUM(L6,L8,L11,L12,L13,L14,-L17) -> 5736782.7
A16: EBITDA margin | B16: =B15/B6 -> 0.10231325 | C16: =C15/C6 -> 0.095145551 | D16: =D15/D6 -> 0.092818053 | E16: =E15/E6 -> 0.086989045 | F16: =F15/F6 -> 0.079166683 | G16: =G15/G6 -> 0.075706168 | H16: =H15/H6 -> 0.078835112 | I16: =I15/I6 -> 0.08125789 | ... L16: =L15/L6 -> 0.087413547
A17: Depreciation and amortisation expense | B17: =-'Source Data'!B68 -> -198146 | C17: =-'Source Data'!C68 -> -247343 | D17: =-'Source Data'!D68 -> -300129 | E17: =-'Source Data'!E68 -> -356828 | F17: =-'Source Data'!F68 -> -409179 | G17: =-'Source Data'!G68 -> -505031 | H17: =-H6*Assumptions!B33 -> -589896.74 | I17: =-I6*Assumptions!C33 -> -682658.04 | J17: =-J6*Assumptions!D33 -> -779516.57 | K17: =-K6*Assumptions!E33 -> -880705.02 | L17: =-L6*Assumptions!F33 -> -984421.11
A18: EBIT | B18: =B15+B17 -> 837859 | C18: =C15+C17 -> 1023993 | D18: =D15+D17 -> 1537819 | E18: =E15+E17 -> 1875855 | F18: =F15+F17 -> 1908330 | G18: =G15+G17 -> 2041282 | H18: =H15+H17 -> 2510408.3 | I18: =I15+I17 -> 3015432.1 | ... L18: =L15+L17 -> 4752361.6
A19: EBIT margin | B19: =B18/B6 -> 0.082744846 | C19: =C18/C6 -> 0.076634642 | D19: =D18/D6 -> 0.077661264 | E19: =E18/E6 -> 0.073086432 | F19: =F18/F6 -> 0.065189026 | G19: =G18/G6 -> 0.060690747 | H19: =H18/H6 -> 0.063835112 | I19: =I18/I6 -> 0.06625789 | ... L19: =L18/L6 -> 0.072413547
A20: Finance income | B20: ='Source Data'!B13 -> 3237 | C20: ='Source Data'!C13 -> 1119 | D20: ='Source Data'!D13 -> 5092 | E20: ='Source Data'!E13 -> 10442 | F20: ='Source Data'!F13 -> 6657 | G20: ='Source Data'!G13 -> 8316 | H20: =G44*Assumptions!B14 -> 19096.28 | I20: =H44*Assumptions!B14 -> 470.06805 | J20: =I44*Assumptions!B14 -> 15582.496 | K20: =J44*Assumptions!B14 -> 43227.902 | L20: =K44*Assumptions!B14 -> 86355.941
A21: Interest expense - debt / leases / bonds | B21: ='Source Data'!B14 -> -30379 | C21: ='Source Data'!C14 -> -26155 | D21: ='Source Data'!D14 -> -124832 | E21: ='Source Data'!E14 -> -127285 | F21: ='Source Data'!F14 -> -90957 | G21: ='Source Data'!G14 -> -67946 | H21: =G21*(1+Assumptions!B53) -> -72702.22 | I21: =H21*(1+Assumptions!C53) -> -77791.375 | J21: =I21*(1+Assumptions!D53) -> -83236.772 | K21: =J21*(1+Assumptions!E53) -> -89063.346 | L21: =K21*(1+Assumptions!F53) -> -95297.78
A22: Interest expense - trade payables | B22: ='Source Data'!B15 -> -18139 | C22: ='Source Data'!C15 -> -20434 | D22: ='Source Data'!D15 -> -15839 | E22: ='Source Data'!E15 -> -19600 | F22: ='Source Data'!F15 -> -29836 | G22: ='Source Data'!G15 -> -54614 | H22: =-G75*Assumptions!B54 -> -57139.929 | I22: =-H75*Assumptions!C54 -> -66917.671 | J22: =-I75*Assumptions!D54 -> -77338.983 | K22: =-J75*Assumptions!E54 -> -88196.285 | L22: =-K75*Assumptions!F54 -> -99514.038
A23: Interest expense - other liabilities | B23: ='Source Data'!B16 -> -3494 | C23: ='Source Data'!C16 -> -56 | D23: ='Source Data'!D16 -> -622 | E23: ='Source Data'!E16 -> -431 | F23: ='Source Data'!F16 -> -560 | G23: ='Source Data'!G16 -> -277 | H23: =-'Debt and WACC'!H19 -> 0 | I23: =-'Debt and WACC'!I19 -> 0 | J23: =-'Debt and WACC'!J19 -> 0 | K23: =-'Debt and WACC'!K19 -> 0 | L23: =-'Debt and WACC'!L19 -> 0
A24: Other finance costs / (income) | B24: ='Source Data'!B17 -> -84 | C24: ='Source Data'!C17 -> -58 | D24: ='Source Data'!D17 -> 0 | E24: ='Source Data'!E17 -> 0 | F24: ='Source Data'!F17 -> -71 | G24: ='Source Data'!G17 -> -108 | H24: =-Assumptions!B56 -> 0 | I24: =-Assumptions!C56 -> 0 | J24: =-Assumptions!D56 -> 0 | K24: =-Assumptions!E56 -> 0 | L24: =-Assumptions!F56 -> 0
A25: Total finance costs | B25: =SUM(B21:B24) -> -52096 | C25: =SUM(C21:C24) -> -46703 | D25: =SUM(D21:D24) -> -141293 | E25: =SUM(E21:E24) -> -147316 | F25: =SUM(F21:F24) -> -121424 | G25: =SUM(G21:G24) -> -122945 | H25: =SUM(H21:H24) -> -129842.15 | I25: =SUM(I21:I24) -> -144709.05 | ... L25: =SUM(L21:L24) -> -194811.82
A26: Profit before tax | B26: =B18+B20+B25 -> 789000 | C26: =C18+C20+C25 -> 978409 | D26: =D18+D20+D25 -> 1401618 | E26: =E18+E20+E25 -> 1738981 | F26: =F18+F20+F25 -> 1793563 | G26: =G18+G20+G25 -> 1926653 | H26: =H18+H20+H25 -> 2399662.5 | I26: =I18+I20+I25 -> 2871193.1 | ... L26: =L18+L20+L25 -> 4643905.7
A27: Income tax | B27: ='Source Data'!B20 -> -145083 | C27: ='Source Data'!C20 -> -173106 | D27: ='Source Data'!D20 -> -269531 | E27: ='Source Data'!E20 -> -333654 | F27: ='Source Data'!F20 -> -287834 | G27: ='Source Data'!G20 -> -367856 | H27: =-H26*Assumptions!B15 -> -455935.87 | I27: =-I26*Assumptions!B15 -> -545526.68 | J27: =-J26*Assumptions!B15 -> -650273.14 | K27: =-K26*Assumptions!B15 -> -766948.13 | L27: =-L26*Assumptions!B15 -> -882342.09
A28: Net profit | B28: =B26+B27 -> 643917 | C28: =C26+C27 -> 805303 | D28: =D26+D27 -> 1132087 | E28: =E26+E27 -> 1405327 | F28: =F26+F27 -> 1505729 | G28: =G26+G27 -> 1558797 | H28: =H26+H27 -> 1943726.6 | I28: =I26+I27 -> 2325666.4 | ... L28: =L26+L27 -> 3761563.6
A29: Net margin | B29: =B28/B6 -> 0.063591622 | C29: =C28/C6 -> 0.060268094 | D29: =D28/D6 -> 0.057171428 | E29: =E28/E6 -> 0.054753878 | F29: =F28/F6 -> 0.051436076 | G29: =G28/G6 -> 0.046345657 | H29: =H28/H6 -> 0.049425428 | I29: =I28/I6 -> 0.051101714 | ... L29: =L28/L6 -> 0.05731638
A30: Statement of cash flows
A31: Net profit | B31: =B28 -> 643917 | C31: =C28 -> 805303 | D31: =D28 -> 1132087 | E31: =E28 -> 1405327 | F31: =F28 -> 1505729 | G31: =G28 -> 1558797 | H31: =H28 -> 1943726.6 | I31: =I28 -> 2325666.4 | ... L31: =L28 -> 3761563.6
A32: Adjustment for depreciation and amortisation | B32: =-B17 -> 198146 | C32: =-C17 -> 247343 | D32: =-D17 -> 300129 | E32: =-E17 -> 356828 | F32: =-F17 -> 409179 | G32: =-G17 -> 505031 | H32: =-H17 -> 589896.74 | I32: =-I17 -> 682658.04 | ... L32: =-L17 -> 984421.11
A33: Change in net working capital and other operating items | B33: =B34-SUM(B31:B32) -> -22141 | C33: =SUM('Source Data'!C32:C35)-SUM('Source Data'!B32:B35) -> 529904 | D33: =SUM('Source Data'!D32:D35)-SUM('Source Data'!C32:C35) -> 757504 | E33: =SUM('Source Data'!E32:E35)-SUM('Source Data'!D32:D35) -> 710654 | F33: =SUM('Source Data'!F32:F35)-SUM('Source Data'!E32:E35) -> 512930 | G33: =SUM('Source Data'!G32:G35)-SUM('Source Data'!F32:F35) -> 468881 | H33: =-(H90-G90) -> -915756.81 | I33: =-(I90-H90) -> 136942.81 | J33: =-(J90-I90) -> 144080.81 | K33: =-(K90-J90) -> 151025.71 | L33: =-(L90-K90) -> 168078.64
A34: Cash flows from operating activities | B34: ='Source Data'!B76 -> 819922 | C34: ='Source Data'!C76 -> 1326331 | D34: ='Source Data'!D76 -> 1253422 | E34: ='Source Data'!E76 -> 1771540 | F34: ='Source Data'!F76 -> 2557453 | G34: ='Source Data'!G76 -> 2697445 | H34: =SUM(H31:H33) -> 1617866.5 | I34: =SUM(I31:I33) -> 3145267.2 | J34: =SUM(J31:J33) -> 3695814.4 | K34: =SUM(K31:K33) -> 4301351.7 | L34: =SUM(L31:L33) -> 4914063.4
A35: Capital expenditures | B35: ='Source Data'!B78 -> -1002025 | C35: ='Source Data'!C78 -> -1335604 | D35: ='Source Data'!D78 -> -1445905 | E35: ='Source Data'!E78 -> -1172863 | F35: ='Source Data'!F78 -> -1561914 | G35: ='Source Data'!G78 -> -2087043 | H35: =-H6*Assumptions!B35 -> -2398913.4 | I35: =-I6*Assumptions!C35 -> -2412058.4 | J35: =-J6*Assumptions!D35 -> -2338549.7 | K35: =-K6*Assumptions!E35 -> -2172405.7 | L35: =-L6*Assumptions!F35 -> -1903214.1
A36: Other investing activities | B36: ='Source Data'!B83-B35 -> 1889 | C36: ='Source Data'!C83-C35 -> 4876 | D36: ='Source Data'!D83-D35 -> 11342 | E36: ='Source Data'!E83-E35 -> 14607 | F36: ='Source Data'!F83-F35 -> -34995 | G36: ='Source Data'!G83-G35 -> 11989 | H36: =Assumptions!B59 -> 0 | I36: =Assumptions!C59 -> 0 | J36: =Assumptions!D59 -> 0 | K36: =Assumptions!E59 -> 0 | L36: =Assumptions!F59 -> 0
A37: Cash flows from investing activities | B37: =SUM(B35:B36) -> -1000136 | C37: =SUM(C35:C36) -> -1330728 | D37: =SUM(D35:D36) -> -1434563 | E37: =SUM(E35:E36) -> -1158256 | F37: =SUM(F35:F36) -> -1596909 | G37: =SUM(G35:G36) -> -2075054 | H37: =SUM(H35:H36) -> -2398913.4 | I37: =SUM(I35:I36) -> -2412058.4 | ... L37: =SUM(L35:L36) -> -1903214.1
A38: Net change in debt / leases / bonds | B38: =SUM('Source Data'!B84:B89) -> 265912 | C38: =SUM('Source Data'!C84:C89) -> -57406 | D38: =SUM('Source Data'!D84:D89) -> 145244 | E38: =SUM('Source Data'!E84:E89) -> -777613 | F38: =SUM('Source Data'!F84:F89) -> -287911 | G38: =SUM('Source Data'!G84:G89) -> -558599 | H38: =Assumptions!B47+Assumptions!B49+Assumptions!B51 -> -150263.7 | I38: =Assumptions!C47+Assumptions!C49+Assumptions!C51 -> 22412.567 | J38: =Assumptions!D47+Assumptions!D49+Assumptions!D51 -> 25005.572 | K38: =Assumptions!E47+Assumptions!E49+Assumptions!E51 -> 27455.962 | L38: =Assumptions!F47+Assumptions!F49+Assumptions!F51 -> 29703.32
A39: Dividends / distributions | B39: =0 -> 0 | C39: =0 -> 0 | D39: =0 -> 0 | E39: =0 -> 0 | F39: =0 -> 0 | G39: =0 -> 0 | H39: =Assumptions!B58 -> 0 | I39: =Assumptions!C58 -> 0 | J39: =Assumptions!D58 -> 0 | K39: =Assumptions!E58 -> 0 | L39: =Assumptions!F58 -> 0
A40: Other financing / balancing item | B40: ='Source Data'!B90-B38-B39 -> 0 | C40: ='Source Data'!C90-C38-C39 -> 0 | D40: ='Source Data'!D90-D38-D39 -> 0 | E40: ='Source Data'!E90-E38-E39 -> 0 | F40: ='Source Data'!F90-F38-F39 -> 0 | G40: ='Source Data'!G90-G38-G39 -> 0 | H40: =Assumptions!B57 -> 0 | I40: =Assumptions!C57 -> 0 | J40: =Assumptions!D57 -> 0 | K40: =Assumptions!E57 -> 0 | L40: =Assumptions!F57 -> 0
...

Sheet Debt and WACC
A1: Debt and WACC schedule
A2: Forecast WACC uses an explicitly stated target capital structure. Market capitalisation is shown for reference only and does not affect WACC weights.
A3: Metric | B3: 2020 | C3: 2021 | D3: 2022 | E3: 2023 | F3: 2024 | G3: 2025 | H3: 2026 | I3: 2027 | J3: 2028 | K3: 2029 | L3: 2030
A4: Period | B4: 2020A | C4: 2021A | D4: 2022A | E4: 2023A | F4: 2024A | G4: 2025A | H4: 2026E | I4: 2027E | J4: 2028E | K4: 2029E | L4: 2030E
A5: Debt schedule
A6: Bank loans (non-current) | B6: ='Source Data'!B47 -> 725851 | C6: ='Source Data'!C47 -> 583014 | D6: ='Source Data'!D47 -> 690862 | E6: ='Source Data'!E47 -> 469629 | F6: ='Source Data'!F47 -> 272219 | G6: ='Source Data'!G47 -> 312861 | H6: =(G6+G7+Assumptions!B47)*(1-Assumptions!B48) -> 310067.29 | I6: =(H6+H7+Assumptions!C47)*(1-Assumptions!C48) -> 303367.29 | J6: =(I6+I7+Assumptions!D47)*(1-Assumptions!D48) -> 296667.29 | K6: =(J6+J7+Assumptions!E47)*(1-Assumptions!E48) -> 289967.29 | L6: =(K6+K7+Assumptions!F47)*(1-Assumptions!F48) -> 283267.29
A7: Bank loans (current) | B7: ='Source Data'!B57 -> 216868 | C7: ='Source Data'!C57 -> 196169 | D7: ='Source Data'!D57 -> 410157 | E7: ='Source Data'!E57 -> 278588 | F7: ='Source Data'!F57 -> 361034 | G7: ='Source Data'!G57 -> 159926 | H7: =(G6+G7+Assumptions!B47)*Assumptions!B48 -> 152719.71 | I7: =(H6+H7+Assumptions!C47)*Assumptions!C48 -> 149419.71 | J7: =(I6+I7+Assumptions!D47)*Assumptions!D48 -> 146119.71 | K7: =(J6+J7+Assumptions!E47)*Assumptions!E48 -> 142819.71 | L7: =(K6+K7+Assumptions!F47)*Assumptions!F48 -> 139519.71
A8: Lease liabilities (non-current) | B8: ='Source Data'!B48 -> 67876 | C8: ='Source Data'!C48 -> 46621 | D8: ='Source Data'!D48 -> 34673 | E8: ='Source Data'!E48 -> 35612 | F8: ='Source Data'!F48 -> 60818 | G8: ='Source Data'!G48 -> 87851 | H8: =(G8+G9+Assumptions!B49)*(1-Assumptions!B50) -> 110915.45 | I8: =(H8+H9+Assumptions!C49)*(1-Assumptions!C50) -> 136521.37 | J8: =(I8+I9+Assumptions!D49)*(1-Assumptions!D50) -> 164175.78 | K8: =(J8+J9+Assumptions!E49)*(1-Assumptions!E50) -> 193765.99 | L8: =(K8+K9+Assumptions!F49)*(1-Assumptions!F50) -> 225131.61
A9: Lease liabilities (current) | B9: ='Source Data'!B58 -> 42249 | C9: ='Source Data'!C58 -> 27721 | D9: ='Source Data'!D58 -> 17893 | E9: ='Source Data'!E58 -> 14565 | F9: ='Source Data'!F58 -> 17900 | G9: ='Source Data'!G58 -> 22812 | H9: =(G8+G9+Assumptions!B49)*Assumptions!B50 -> 29483.853 | I9: =(H8+H9+Assumptions!C49)*Assumptions!C50 -> 36290.492 | J9: =(I8+I9+Assumptions!D49)*Assumptions!D50 -> 43641.662 | K9: =(J8+J9+Assumptions!E49)*Assumptions!E50 -> 51507.414 | L9: =(K8+K9+Assumptions!F49)*Assumptions!F50 -> 59845.112
A10: Bonds (non-current) | B10: ='Source Data'!B49 -> 419936 | C10: ='Source Data'!C49 -> 450000 | D10: ='Source Data'!D49 -> 370000 | E10: ='Source Data'!E49 -> 370000 | F10: ='Source Data'!F49 -> 170000 | G10: ='Source Data'!G49 -> 0 | H10: =(G10+G11+Assumptions!B51)*(1-Assumptions!B52) -> 1411.5 | I10: =(H10+H11+Assumptions!C51)*(1-Assumptions!C52) -> 1411.5 | J10: =(I10+I11+Assumptions!D51)*(1-Assumptions!D52) -> 1411.5 | K10: =(J10+J11+Assumptions!E51)*(1-Assumptions!E52) -> 1411.5 | L10: =(K10+K11+Assumptions!F51)*(1-Assumptions!F52) -> 1411.5
A11: Bonds (current) | B11: ='Source Data'!B59 -> 930 | C11: ='Source Data'!C59 -> 171642 | D11: ='Source Data'!D59 -> 260947 | E11: ='Source Data'!E59 -> 4784 | F11: ='Source Data'!F59 -> 204845 | G11: ='Source Data'!G59 -> 171882 | H11: =(G10+G11+Assumptions!B51)*Assumptions!B52 -> 470.5 | I11: =(H10+H11+Assumptions!C51)*Assumptions!C52 -> 470.5 | J11: =(I10+I11+Assumptions!D51)*Assumptions!D52 -> 470.5 | K11: =(J10+J11+Assumptions!E51)*Assumptions!E52 -> 470.5 | L11: =(K10+K11+Assumptions!F51)*Assumptions!F52 -> 470.5
A12: Total interest-bearing debt | B12: ='Three-Statement Model'!B88 -> 1473710 | C12: ='Three-Statement Model'!C88 -> 1475167 | D12: ='Three-Statement Model'!D88 -> 1784532 | E12: ='Three-Statement Model'!E88 -> 1173178 | F12: ='Three-Statement Model'!F88 -> 1086816 | G12: ='Three-Statement Model'!G88 -> 755332 | H12: =SUM(H6:H11) -> 605068.3 | I12: =SUM(I6:I11) -> 627480.87 | J12: =SUM(J6:J11) -> 652486.44 | K12: =SUM(K6:K11) -> 679942.4 | L12: =SUM(L6:L11) -> 709645.72
A13: Cash and cash equivalents | B13: ='Three-Statement Model'!B44 -> 480418 | C13: ='Three-Statement Model'!C44 -> 418615 | D13: ='Three-Statement Model'!D44 -> 382718 | E13: ='Three-Statement Model'!E44 -> 218389 | F13: ='Three-Statement Model'!F44 -> 891022 | G13: ='Three-Statement Model'!G44 -> 954814 | H13: ='Three-Statement Model'!H56 -> 23503.402 | I13: ='Three-Statement Model'!I56 -> 779124.82 | J13: ='Three-Statement Model'!J56 -> 2161395.1 | K13: ='Three-Statement Model'!K56 -> 4317797.1 | L13: ='Three-Statement Model'!L56 -> 7358349.6
A14: Net debt | B14: =B12-B13 -> 993292 | C14: =C12-C13 -> 1056552 | D14: =D12-D13 -> 1401814 | E14: =E12-E13 -> 954789 | F14: =F12-F13 -> 195794 | G14: =G12-G13 -> -199482 | H14: =H12-H13 -> 581564.9 | I14: =I12-I13 -> -151643.95 | ... L14: =L12-L13 -> -6648703.9
A15: Average total debt | B15: =B12 -> 1473710 | C15: =AVERAGE(B12,C12) -> 1474438.5 | D15: =AVERAGE(C12,D12) -> 1629849.5 | E15: =AVERAGE(D12,E12) -> 1478855 | F15: =AVERAGE(E12,F12) -> 1129997 | G15: =AVERAGE(F12,G12) -> 921074 | H15: =AVERAGE(G12,H12) -> 680200.15 | I15: =AVERAGE(H12,I12) -> 616274.58 | J15: =AVERAGE(I12,J12) -> 639983.65 | ... L15: =AVERAGE(K12,L12) -> 694794.06
A16: Breakdown of interest on liabilities
A17: Total finance interest expense | B17: =-'Source Data'!B18 -> 52096 | C17: =-'Source Data'!C18 -> 46703 | D17: =-'Source Data'!D18 -> 141293 | E17: =-'Source Data'!E18 -> 147316 | F17: =-'Source Data'!F18 -> 121424 | G17: =-'Source Data'!G18 -> 122945 | H17: =H20+H18+H19 -> 104753.94 | I17: =I20+I18+I19 -> 110056.89 | J17: =J20+J18+J19 -> 122137.84 | K17: =K20+K18+K19 -> 134831.29 | L17: =L20+L18+L19 -> 148149.62
A18: Interest expense - trade payables | B18: =-'Three-Statement Model'!B22 -> 18139 | C18: =-'Three-Statement Model'!C22 -> 20434 | D18: =-'Three-Statement Model'!D22 -> 15839 | E18: =-'Three-Statement Model'!E22 -> 19600 | F18: =-'Three-Statement Model'!F22 -> 29836 | G18: =-'Three-Statement Model'!G22 -> 54614 | H18: ='Three-Statement Model'!G75*Assumptions!B54 -> 57139.929 | I18: ='Three-Statement Model'!H75*Assumptions!C54 -> 66917.671 | J18: ='Three-Statement Model'!I75*Assumptions!D54 -> 77338.983 | K18: ='Three-Statement Model'!J75*Assumptions!E54 -> 88196.285 | L18: ='Three-Statement Model'!K75*Assumptions!F54 -> 99514.038
A19: Interest expense - other | B19: =-SUM('Three-Statement Model'!B23,'Three-Statement Model'!B24) -> 3578 | C19: =-SUM('Three-Statement Model'!C23,'Three-Statement Model'!C24) -> 114 | D19: =-SUM('Three-Statement Model'!D23,'Three-Statement Model'!D24) -> 622 | E19: =-SUM('Three-Statement Model'!E23,'Three-Statement Model'!E24) -> 431 | F19: =-SUM('Three-Statement Model'!F23,'Three-Statement Model'!F24) -> 631 | G19: =-SUM('Three-Statement Model'!G23,'Three-Statement Model'!G24) -> 385 | H19: 0 | I19: 0 | J19: 0 | K19: 0 | L19: 0
A20: Interest expense - debt / leases / bonds | B20: =-'Three-Statement Model'!B21 -> 30379 | C20: =-'Three-Statement Model'!C21 -> 26155 | D20: =-'Three-Statement Model'!D21 -> 124832 | E20: =-'Three-Statement Model'!E21 -> 127285 | F20: =-'Three-Statement Model'!F21 -> 90957 | G20: =-'Three-Statement Model'!G21 -> 67946 | H20: =H15*Assumptions!B53 -> 47614.011 | I20: =I15*Assumptions!C53 -> 43139.221 | J20: =J15*Assumptions!D53 -> 44798.856 | K20: =K15*Assumptions!E53 -> 46635.009 | L20: =L15*Assumptions!F53 -> 48635.584
A21: Pre-tax cost of debt | B21: =B20/B15 -> 0.020613961 | C21: =C20/C15 -> 0.017738956 | D21: =D20/D15 -> 0.076591121 | E21: =E20/E15 -> 0.086069966 | F21: =F20/F15 -> 0.080493134 | G21: =G20/G15 -> 0.073768231 | H21: =H20/H15 -> 0.07 | I21: =I20/I15 -> 0.07 | ... L21: =L20/L15 -> 0.07
A22: WACC calculation
A23: Reference market price / share (PLN) | B23: =Assumptions!B22 -> 200 | C23: =Assumptions!C22 -> 300 | D23: =Assumptions!D22 -> 330 | E23: =Assumptions!E22 -> 420 | F23: =Assumptions!F22 -> 400 | G23: =Assumptions!G22 -> 41 | H23: =(H25-H14)/Assumptions!$B$10 -> 46.841097 | I23: =(I25-I14)/Assumptions!$B$10 -> 56.735001 | J23: =(J25-J14)/Assumptions!$B$10 -> 68.047643 | K23: =(K25-K14)/Assumptions!$B$10 -> 80.994943 | L23: =(L25-L14)/Assumptions!$B$10 -> 94.553697
A24: Number of shares (thousand) | B24: =Assumptions!B24 -> 98040 | C24: =Assumptions!C24 -> 98040 | D24: =Assumptions!D24 -> 98040 | E24: =Assumptions!E24 -> 98040 | F24: =Assumptions!F24 -> 98040 | G24: =Assumptions!G24 -> 980400 | H24: =Assumptions!B10 -> 980400 | I24: =Assumptions!B10 -> 980400 | J24: =Assumptions!B10 -> 980400 | K24: =Assumptions!B10 -> 980400 | L24: =Assumptions!B10 -> 980400
A25: Reference market capitalisation | B25: =B23*B24 -> 19608000 | C25: =C23*C24 -> 29412000 | D25: =D23*D24 -> 32353200 | E25: =E23*E24 -> 41176800 | F25: =F23*F24 -> 39216000 | G25: =G23*G24 -> 40196400 | H25: =Assumptions!$B$4*'Three-Statement Model'!H15 -> 46504576 | I25: =Assumptions!$B$4*'Three-Statement Model'!I15 -> 55471351 | J25: =Assumptions!$B$4*'Three-Statement Model'!J15 -> 65205000 | K25: =Assumptions!$B$4*'Three-Statement Model'!K15 -> 75769588 | L25: =Assumptions!$B$4*'Three-Statement Model'!L15 -> 86051740
A26: Enterprise value | B26: =B25+B14 -> 20601292 | C26: =C25+C14 -> 30468552 | D26: =D25+D14 -> 33755014 | E26: =E25+E14 -> 42131589 | F26: =F25+F14 -> 39411794 | G26: =G25+G14 -> 39996918 | H26: =H25+H14 -> 47086141 | I26: =I25+I14 -> 55319707 | ... L26: =L25+L14 -> 79403037
A27: Tax rate | B27: =-'Source Data'!B20/'Source Data'!B19 -> 0.18388213 | C27: =-'Source Data'!C20/'Source Data'!C19 -> 0.17692601 | D27: =-'Source Data'!D20/'Source Data'!D19 -> 0.1922999 | E27: =-'Source Data'!E20/'Source Data'!E19 -> 0.19186754 | F27: =-'Source Data'!F20/'Source Data'!F19 -> 0.16048168 | G27: =-'Source Data'!G20/'Source Data'!G19 -> 0.19093007 | H27: =Assumptions!B15 -> 0.19 | I27: =Assumptions!B15 -> 0.19 | J27: =Assumptions!B15 -> 0.19 | K27: =Assumptions!B15 -> 0.19 | L27: =Assumptions!B15 -> 0.19
A28: After-tax cost of debt | B28: =B21*(1-B27) -> 0.016823422 | C28: =C21*(1-C27) -> 0.014600473 | D28: =D21*(1-D27) -> 0.061862656 | E28: =E21*(1-E27) -> 0.069555934 | F28: =F21*(1-F27) -> 0.067575461 | G28: =G21*(1-G27) -> 0.059683658 | H28: =H21*(1-H27) -> 0.0567 | I28: =I21*(1-I27) -> 0.0567 | ... L28: =L21*(1-L27) -> 0.0567
A29: Risk-free rate | B29: =Assumptions!B23 -> 0.015 | C29: =Assumptions!C23 -> 0.0194 | D29: =Assumptions!D23 -> 0.0605 | E29: =Assumptions!E23 -> 0.0581 | F29: =Assumptions!F23 -> 0.0553 | G29: =Assumptions!G23 -> 0.055 | H29: =Assumptions!B5 -> 0.0588 | I29: =Assumptions!B5 -> 0.0588 | J29: =Assumptions!B5 -> 0.0588 | K29: =Assumptions!B5 -> 0.0588 | L29: =Assumptions!B5 -> 0.0588
A30: Beta | B30: =Assumptions!B6 -> 0.67333333 | C30: =Assumptions!B6 -> 0.67333333 | D30: =Assumptions!B6 -> 0.67333333 | E30: =Assumptions!B6 -> 0.67333333 | F30: =Assumptions!B6 -> 0.67333333 | G30: =Assumptions!B6 -> 0.67333333 | H30: =Assumptions!B6 -> 0.67333333 | I30: =Assumptions!B6 -> 0.67333333 | J30: =Assumptions!B6 -> 0.67333333 | K30: =Assumptions!B6 -> 0.67333333 | L30: =Assumptions!B6 -> 0.67333333
A31: Equity risk premium | B31: =Assumptions!B7 -> 0.0533 | C31: =Assumptions!B7 -> 0.0533 | D31: =Assumptions!B7 -> 0.0533 | E31: =Assumptions!B7 -> 0.0533 | F31: =Assumptions!B7 -> 0.0533 | G31: =Assumptions!B7 -> 0.0533 | H31: =Assumptions!B7 -> 0.0533 | I31: =Assumptions!B7 -> 0.0533 | J31: =Assumptions!B7 -> 0.0533 | K31: =Assumptions!B7 -> 0.0533 | L31: =Assumptions!B7 -> 0.0533
A32: Cost of equity | B32: =B29+B30*B31 -> 0.050888667 | C32: =C29+C30*C31 -> 0.055288667 | D32: =D29+D30*D31 -> 0.096388667 | E32: =E29+E30*E31 -> 0.093988667 | F32: =F29+F30*F31 -> 0.091188667 | G32: =G29+G30*G31 -> 0.090888667 | H32: =H29+H30*H31 -> 0.094688667 | I32: =I29+I30*I31 -> 0.094688667 | ... L32: =L29+L30*L31 -> 0.094688667
A33: Target equity weight / actual equity weight | B33: ='Three-Statement Model'!B65/('Three-Statement Model'!B65+B12) -> 0.60598865 | C33: ='Three-Statement Model'!C65/('Three-Statement Model'!C65+C12) -> 0.6754563 | D33: ='Three-Statement Model'!D65/('Three-Statement Model'!D65+D12) -> 0.70199764 | E33: ='Three-Statement Model'!E65/('Three-Statement Model'!E65+E12) -> 0.82692633 | F33: ='Three-Statement Model'!F65/('Three-Statement Model'!F65+F12) -> 0.86728748 | G33: ='Three-Statement Model'!G65/('Three-Statement Model'!G65+G12) -> 0.91987096 | H33: =Assumptions!B16 -> 0.95 | I33: =Assumptions!B16 -> 0.95 | J33: =Assumptions!B16 -> 0.95 | K33: =Assumptions!B16 -> 0.95 | L33: =Assumptions!B16 -> 0.95
A34: Target debt weight / actual debt weight | B34: =1-B33 -> 0.39401135 | C34: =1-C33 -> 0.3245437 | D34: =1-D33 -> 0.29800236 | E34: =1-E33 -> 0.17307367 | F34: =1-F33 -> 0.13271252 | G34: =1-G33 -> 0.080129041 | H34: =Assumptions!B17 -> 0.05 | I34: =Assumptions!B17 -> 0.05 | J34: =Assumptions!B17 -> 0.05 | K34: =Assumptions!B17 -> 0.05 | L34: =Assumptions!B17 -> 0.05
A35: WACC | B35: =B32*B33+B28*B34 -> 0.037466574 | C35: =C32*C33+C28*C34 -> 0.04208357 | D35: =D32*D33+D28*D34 -> 0.086099834 | E35: =E32*E33+E28*E34 -> 0.089760004 | F35: =F32*F33+F28*F34 -> 0.088054899 | G35: =G32*G33+G28*G34 -> 0.088388239 | H35: =H32*H33+H28*H34 -> 0.092789233 | I35: =I32*I33+I28*I34 -> 0.092789233 | ... L35: =L32*L33+L28*L34 -> 0.092789233

Sheet DCF Valuation
A1: DCF Valuation | I1: Sensitivity analysis — implied value / share (PLN)
A2: Nominal unlevered DCF with two capital expenditure scenarios. Scenario 1 assumes continued growth in capital expenditures; Scenario 2 assumes that capital expenditures in the terminal year equal depreciation and amortisation. | I2: Rows = terminal growth; columns = WACC. Formulas reference the existing DCF and do not change model assumptions.
A3: Metric | B3: 2026E | C3: 2027E | D3: 2028E | E3: 2029E | F3: 2030E | G3: Terminal
A4: Key valuation assumptions | I4: Scenario 1: continued growth in capital expenditures
A5: WACC | B5: ='Debt and WACC'!H35 -> 0.092789233 | I5: g \ WACC | J5: =$B$5-1% -> 0.082789233 | K5: =$B$5-0.5% -> 0.087789233 | L5: =$B$5 -> 0.092789233 | M5: =$B$5+0.5% -> 0.097789233 | N5: =$B$5+1% -> 0.10278923
A6: Terminal growth rate | B6: =Assumptions!B8 -> 0.025 | I6: =$B$6-1% -> 0.015 | J6: =IF(J$5>$I6,((SUMPRODUCT($B$14:$F$14,1/(1+J$5)^$B$16:$F$16)+($F$14*(1+$I6)/(J$5-$I6))/(1+J$5)^$F$16)-$B$23)/$B$25,NA()) -> 37.055642 | K6: =IF(K$5>$I6,((SUMPRODUCT($B$14:$F$14,1/(1+K$5)^$B$16:$F$16)+($F$14*(1+$I6)/(K$5-$I6))/(1+K$5)^$F$16)-$B$23)/$B$25,NA()) -> 34.098548 | L6: =IF(L$5>$I6,((SUMPRODUCT($B$14:$F$14,1/(1+L$5)^$B$16:$F$16)+($F$14*(1+$I6)/(L$5-$I6))/(1+L$5)^$F$16)-$B$23)/$B$25,NA()) -> 31.528434 | M6: =IF(M$5>$I6,((SUMPRODUCT($B$14:$F$14,1/(1+M$5)^$B$16:$F$16)+($F$14*(1+$I6)/(M$5-$I6))/(1+M$5)^$F$16)-$B$23)/$B$25,NA()) -> 29.275037 | N6: =IF(N$5>$I6,((SUMPRODUCT($B$14:$F$14,1/(1+N$5)^$B$16:$F$16)+($F$14*(1+$I6)/(N$5-$I6))/(1+N$5)^$F$16)-$B$23)/$B$25,NA()) -> 27.284105
A7: Unlevered free cash flows | I7: =$B$6-0.5% -> 0.02 | J7: =IF(J$5>$I7,((SUMPRODUCT($B$14:$F$14,1/(1+J$5)^$B$16:$F$16)+($F$14*(1+$I7)/(J$5-$I7))/(1+J$5)^$F$16)-$B$23)/$B$25,NA()) -> 39.756641 | K7: =IF(K$5>$I7,((SUMPRODUCT($B$14:$F$14,1/(1+K$5)^$B$16:$F$16)+($F$14*(1+$I7)/(K$5-$I7))/(1+K$5)^$F$16)-$B$23)/$B$25,NA()) -> 36.385932 | L7: =IF(L$5>$I7,((SUMPRODUCT($B$14:$F$14,1/(1+L$5)^$B$16:$F$16)+($F$14*(1+$I7)/(L$5-$I7))/(1+L$5)^$F$16)-$B$23)/$B$25,NA()) -> 33.485538 | M7: =IF(M$5>$I7,((SUMPRODUCT($B$14:$F$14,1/(1+M$5)^$B$16:$F$16)+($F$14*(1+$I7)/(M$5-$I7))/(1+M$5)^$F$16)-$B$23)/$B$25,NA()) -> 30.96461 | N7: =IF(N$5>$I7,((SUMPRODUCT($B$14:$F$14,1/(1+N$5)^$B$16:$F$16)+($F$14*(1+$I7)/(N$5-$I7))/(1+N$5)^$F$16)-$B$23)/$B$25,NA()) -> 28.754252
A8: EBIT | B8: ='Three-Statement Model'!H18 -> 2510408.3 | C8: ='Three-Statement Model'!I18 -> 3015432.1 | D8: ='Three-Statement Model'!J18 -> 3567483.5 | E8: ='Three-Statement Model'!K18 -> 4170600.8 | F8: ='Three-Statement Model'!L18 -> 4752361.6 | I8: =$B$6 -> 0.025 | J8: =IF(J$5>$I8,((SUMPRODUCT($B$14:$F$14,1/(1+J$5)^$B$16:$F$16)+($F$14*(1+$I8)/(J$5-$I8))/(1+J$5)^$F$16)-$B$23)/$B$25,NA()) -> 42.925028 | K8: =IF(K$5>$I8,((SUMPRODUCT($B$14:$F$14,1/(1+K$5)^$B$16:$F$16)+($F$14*(1+$I8)/(K$5-$I8))/(1+K$5)^$F$16)-$B$23)/$B$25,NA()) -> 39.037612 | L8: =IF(L$5>$I8,((SUMPRODUCT($B$14:$F$14,1/(1+L$5)^$B$16:$F$16)+($F$14*(1+$I8)/(L$5-$I8))/(1+L$5)^$F$16)-$B$23)/$B$25,NA()) -> 35.731345 | M8: =IF(M$5>$I8,((SUMPRODUCT($B$14:$F$14,1/(1+M$5)^$B$16:$F$16)+($F$14*(1+$I8)/(M$5-$I8))/(1+M$5)^$F$16)-$B$23)/$B$25,NA()) -> 32.886301 | N8: =IF(N$5>$I8,((SUMPRODUCT($B$14:$F$14,1/(1+N$5)^$B$16:$F$16)+($F$14*(1+$I8)/(N$5-$I8))/(1+N$5)^$F$16)-$B$23)/$B$25,NA()) -> 30.413391
A9: Cash taxes on EBIT | B9: =-B8*Assumptions!B15 -> -476977.58 | C9: =-C8*Assumptions!B15 -> -572932.09 | D9: =-D8*Assumptions!B15 -> -677821.86 | E9: =-E8*Assumptions!B15 -> -792414.16 | F9: =-F8*Assumptions!B15 -> -902948.7 | I9: =$B$6+0.5% -> 0.03 | J9: =IF(J$5>$I9,((SUMPRODUCT($B$14:$F$14,1/(1+J$5)^$B$16:$F$16)+($F$14*(1+$I9)/(J$5-$I9))/(1+J$5)^$F$16)-$B$23)/$B$25,NA()) -> 46.69361 | K9: =IF(K$5>$I9,((SUMPRODUCT($B$14:$F$14,1/(1+K$5)^$B$16:$F$16)+($F$14*(1+$I9)/(K$5-$I9))/(1+K$5)^$F$16)-$B$23)/$B$25,NA()) -> 42.148146 | L9: =IF(L$5>$I9,((SUMPRODUCT($B$14:$F$14,1/(1+L$5)^$B$16:$F$16)+($F$14*(1+$I9)/(L$5-$I9))/(1+L$5)^$F$16)-$B$23)/$B$25,NA()) -> 38.334827 | M9: =IF(M$5>$I9,((SUMPRODUCT($B$14:$F$14,1/(1+M$5)^$B$16:$F$16)+($F$14*(1+$I9)/(M$5-$I9))/(1+M$5)^$F$16)-$B$23)/$B$25,NA()) -> 35.091472 | N9: =IF(N$5>$I9,((SUMPRODUCT($B$14:$F$14,1/(1+N$5)^$B$16:$F$16)+($F$14*(1+$I9)/(N$5-$I9))/(1+N$5)^$F$16)-$B$23)/$B$25,NA()) -> 32.300466
A10: NOPAT | B10: =B8+B9 -> 2033430.7 | C10: =C8+C9 -> 2442500 | D10: =D8+D9 -> 2889661.6 | E10: =E8+E9 -> 3378186.7 | F10: =F8+F9 -> 3849412.9 | I10: =$B$6+1% -> 0.035 | J10: =IF(J$5>$I10,((SUMPRODUCT($B$14:$F$14,1/(1+J$5)^$B$16:$F$16)+($F$14*(1+$I10)/(J$5-$I10))/(1+J$5)^$F$16)-$B$23)/$B$25,NA()) -> 51.250777 | K10: =IF(K$5>$I10,((SUMPRODUCT($B$14:$F$14,1/(1+K$5)^$B$16:$F$16)+($F$14*(1+$I10)/(K$5-$I10))/(1+K$5)^$F$16)-$B$23)/$B$25,NA()) -> 45.847916 | L10: =IF(L$5>$I10,((SUMPRODUCT($B$14:$F$14,1/(1+L$5)^$B$16:$F$16)+($F$14*(1+$I10)/(L$5-$I10))/(1+L$5)^$F$16)-$B$23)/$B$25,NA()) -> 41.388821 | M10: =IF(M$5>$I10,((SUMPRODUCT($B$14:$F$14,1/(1+M$5)^$B$16:$F$16)+($F$14*(1+$I10)/(M$5-$I10))/(1+M$5)^$F$16)-$B$23)/$B$25,NA()) -> 37.647845 | N10: =IF(N$5>$I10,((SUMPRODUCT($B$14:$F$14,1/(1+N$5)^$B$16:$F$16)+($F$14*(1+$I10)/(N$5-$I10))/(1+N$5)^$F$16)-$B$23)/$B$25,NA()) -> 34.465916
A11: Adjustment for depreciation and amortisation | B11: ='Three-Statement Model'!H32 -> 589896.74 | C11: ='Three-Statement Model'!I32 -> 682658.04 | D11: ='Three-Statement Model'!J32 -> 779516.57 | E11: ='Three-Statement Model'!K32 -> 880705.02 | F11: ='Three-Statement Model'!L32 -> 984421.11
A12: Capital expenditures | B12: ='Three-Statement Model'!H35 -> -2398913.4 | C12: ='Three-Statement Model'!I35 -> -2412058.4 | D12: ='Three-Statement Model'!J35 -> -2338549.7 | E12: ='Three-Statement Model'!K35 -> -2172405.7 | F12: ='Three-Statement Model'!L35 -> -1903214.1 | I12: Scenario 2: terminal-year capital expenditures = depreciation and amortisation
A13: Less: change in operating net working capital | B13: ='Three-Statement Model'!H90-'Three-Statement Model'!G90 -> 915756.81 | C13: ='Three-Statement Model'!I90-'Three-Statement Model'!H90 -> -136942.81 | D13: ='Three-Statement Model'!J90-'Three-Statement Model'!I90 -> -144080.81 | E13: ='Three-Statement Model'!K90-'Three-Statement Model'!J90 -> -151025.71 | F13: ='Three-Statement Model'!L90-'Three-Statement Model'!K90 -> -168078.64 | I13: g \ WACC | J13: =$B$5-1% -> 0.082789233 | K13: =$B$5-0.5% -> 0.087789233 | L13: =$B$5 -> 0.092789233 | M13: =$B$5+0.5% -> 0.097789233 | N13: =$B$5+1% -> 0.10278923
A14: Unlevered free cash flows | B14: =SUM(B10:B12)-B13 -> -691342.74 | C14: =SUM(C10:C12)-C13 -> 850042.42 | D14: =SUM(D10:D12)-D13 -> 1474709.3 | E14: =SUM(E10:E12)-E13 -> 2237511.7 | F14: =SUM(F10:F12)-F13 -> 3098698.5 | I14: =$B$6-1% -> 0.015 | J14: =IF(J$13>$I14,((SUMPRODUCT($B$14:$F$14,1/(1+J$13)^$B$16:$F$16)+($B$34*(1+$I14)/(J$13-$I14))/(1+J$13)^$F$16)-$B$23)/$B$25,NA()) -> 46.483219 | K14: =IF(K$13>$I14,((SUMPRODUCT($B$14:$F$14,1/(1+K$13)^$B$16:$F$16)+($B$34*(1+$I14)/(K$13-$I14))/(1+K$13)^$F$16)-$B$23)/$B$25,NA()) -> 42.678592 | L14: =IF(L$13>$I14,((SUMPRODUCT($B$14:$F$14,1/(1+L$13)^$B$16:$F$16)+($B$34*(1+$I14)/(L$13-$I14))/(1+L$13)^$F$16)-$B$23)/$B$25,NA()) -> 39.374987 | M14: =IF(M$13>$I14,((SUMPRODUCT($B$14:$F$14,1/(1+M$13)^$B$16:$F$16)+($B$34*(1+$I14)/(M$13-$I14))/(1+M$13)^$F$16)-$B$23)/$B$25,NA()) -> 36.481327 | N14: =IF(N$13>$I14,((SUMPRODUCT($B$14:$F$14,1/(1+N$13)^$B$16:$F$16)+($B$34*(1+$I14)/(N$13-$I14))/(1+N$13)^$F$16)-$B$23)/$B$25,NA()) -> 33.927294
A15: Discounting | I15: =$B$6-0.5% -> 0.02 | J15: =IF(J$13>$I15,((SUMPRODUCT($B$14:$F$14,1/(1+J$13)^$B$16:$F$16)+($B$34*(1+$I15)/(J$13-$I15))/(1+J$13)^$F$16)-$B$23)/$B$25,NA()) -> 49.985089 | K15: =IF(K$13>$I15,((SUMPRODUCT($B$14:$F$14,1/(1+K$13)^$B$16:$F$16)+($B$34*(1+$I15)/(K$13-$I15))/(1+K$13)^$F$16)-$B$23)/$B$25,NA()) -> 45.644207 | L15: =IF(L$13>$I15,((SUMPRODUCT($B$14:$F$14,1/(1+L$13)^$B$16:$F$16)+($B$34*(1+$I15)/(L$13-$I15))/(1+L$13)^$F$16)-$B$23)/$B$25,NA()) -> 41.91239 | M15: =IF(M$13>$I15,((SUMPRODUCT($B$14:$F$14,1/(1+M$13)^$B$16:$F$16)+($B$34*(1+$I15)/(M$13-$I15))/(1+M$13)^$F$16)-$B$23)/$B$25,NA()) -> 38.671874 | N15: =IF(N$13>$I15,((SUMPRODUCT($B$14:$F$14,1/(1+N$13)^$B$16:$F$16)+($B$34*(1+$I15)/(N$13-$I15))/(1+N$13)^$F$16)-$B$23)/$B$25,NA()) -> 35.833353
A16: Discount period | B16: =1 -> 1 | C16: =2 -> 2 | D16: =3 -> 3 | E16: =4 -> 4 | F16: =5 -> 5 | I16: =$B$6 -> 0.025 | J16: =IF(J$13>$I16,((SUMPRODUCT($B$14:$F$14,1/(1+J$13)^$B$16:$F$16)+($B$34*(1+$I16)/(J$13-$I16))/(1+J$13)^$F$16)-$B$23)/$B$25,NA()) -> 54.092932 | K16: =IF(K$13>$I16,((SUMPRODUCT($B$14:$F$14,1/(1+K$13)^$B$16:$F$16)+($B$34*(1+$I16)/(K$13-$I16))/(1+K$13)^$F$16)-$B$23)/$B$25,NA()) -> 49.082135 | L16: =IF(L$13>$I16,((SUMPRODUCT($B$14:$F$14,1/(1+L$13)^$B$16:$F$16)+($B$34*(1+$I16)/(L$13-$I16))/(1+L$13)^$F$16)-$B$23)/$B$25,NA()) -> 44.8241 | M16: =IF(M$13>$I16,((SUMPRODUCT($B$14:$F$14,1/(1+M$13)^$B$16:$F$16)+($B$34*(1+$I16)/(M$13-$I16))/(1+M$13)^$F$16)-$B$23)/$B$25,NA()) -> 41.163364 | N16: =IF(N$13>$I16,((SUMPRODUCT($B$14:$F$14,1/(1+N$13)^$B$16:$F$16)+($B$34*(1+$I16)/(N$13-$I16))/(1+N$13)^$F$16)-$B$23)/$B$25,NA()) -> 37.984442
A17: Discount factor | B17: =1/(1+$B$5)^B16 -> 0.91508954 | C17: =1/(1+$B$5)^C16 -> 0.83738887 | D17: =1/(1+$B$5)^D16 -> 0.7662858 | E17: =1/(1+$B$5)^E16 -> 0.70122012 | F17: =1/(1+$B$5)^F16 -> 0.6416792 | I17: =$B$6+0.5% -> 0.03 | J17: =IF(J$13>$I17,((SUMPRODUCT($B$14:$F$14,1/(1+J$13)^$B$16:$F$16)+($B$34*(1+$I17)/(J$13-$I17))/(1+J$13)^$F$16)-$B$23)/$B$25,NA()) -> 58.978934 | K17: =IF(K$13>$I17,((SUMPRODUCT($B$14:$F$14,1/(1+K$13)^$B$16:$F$16)+($B$34*(1+$I17)/(K$13-$I17))/(1+K$13)^$F$16)-$B$23)/$B$25,NA()) -> 53.114971 | L17: =IF(L$13>$I17,((SUMPRODUCT($B$14:$F$14,1/(1+L$13)^$B$16:$F$16)+($B$34*(1+$I17)/(L$13-$I17))/(1+L$13)^$F$16)-$B$23)/$B$25,NA()) -> 48.199538 | M17: =IF(M$13>$I17,((SUMPRODUCT($B$14:$F$14,1/(1+M$13)^$B$16:$F$16)+($B$34*(1+$I17)/(M$13-$I17))/(1+M$13)^$F$16)-$B$23)/$B$25,NA()) -> 44.022389 | N17: =IF(N$13>$I17,((SUMPRODUCT($B$14:$F$14,1/(1+N$13)^$B$16:$F$16)+($B$34*(1+$I17)/(N$13-$I17))/(1+N$13)^$F$16)-$B$23)/$B$25,NA()) -> 40.431053
